<?xml version="1.0"?>
<robot name="basic_robot">
  <material name="blue">
    <color rgba="0 0 1 1"/>
  </material>
  <material name="red">
    <color rgba="1 0 0 1"/>
  </material>
  <material name="green">
    <color rgba="0 1 0 1"/>
  </material>

  <link name="chassis">
    <visual>
      <geometry>
        <box size="0.825 0.825 0.075"/>
      </geometry>
    </visual>
    <collision>
      <geometry>
        <box size="0.825 0.825 0.075"/>
      </geometry>
    </collision>
    <inertial>
      <mass value="10.0"/>
      <inertia ixx="0.57" ixy="0.0" ixz="0.0" iyy="0.57" iyz="0.0" izz="1.13"/>
    </inertial>
  </link>

  <link name="left_wheel">
    <visual>
      <geometry>
        <cylinder radius="0.4" length="0.05"/>
      </geometry>
      <material name="blue"/>
    </visual>
    <visual>
      <origin xyz="0.2 0 0" rpy="0 0 0"/>
      <geometry>
        <box size="0.1 0.1 0.06"/>
      </geometry>
      <material name="green"/>
    </visual>
    <collision>
      <geometry>
        <cylinder radius="0.4" length="0.05"/>
      </geometry>
    </collision>
    <inertial>
      <mass value="2.0"/>
      <inertia ixx="0.08" ixy="0.0" ixz="0.0" iyy="0.08" iyz="0.0" izz="0.16"/>
    </inertial>
  </link>

  <joint name="left_wheel_joint" type="continuous">
    <parent link="chassis"/>
    <child link="left_wheel"/>
    <origin xyz="0 0.4375 0" rpy="-1.570796 0 0"/>
    <axis xyz="0 0 1"/>
  </joint>

  <link name="right_wheel">
    <visual>
      <geometry>
        <cylinder radius="0.4" length="0.05"/>
      </geometry>
      <material name="red"/>
    </visual>
    <visual>
      <origin xyz="0.2 0 0" rpy="0 0 0"/>
      <geometry>
        <box size="0.1 0.1 0.06"/>
      </geometry>
      <material name="green"/>
    </visual>
    <collision>
      <geometry>
        <cylinder radius="0.4" length="0.05"/>
      </geometry>
    </collision>
    <inertial>
      <mass value="2.0"/>
      <inertia ixx="0.08" ixy="0.0" ixz="0.0" iyy="0.08" iyz="0.0" izz="0.16"/>
    </inertial>
  </link>

  <joint name="right_wheel_joint" type="continuous">
    <parent link="chassis"/>
    <child link="right_wheel"/>
    <origin xyz="0 -0.4375 0" rpy="-1.570796 0 0"/>
    <axis xyz="0 0 1"/>
  </joint>

  <!-- Front Caster -->
  <link name="front_caster">
    <visual>
      <geometry>
        <sphere radius="0.1"/>
      </geometry>
      <material name="blue"/>
    </visual>
    <collision>
      <geometry>
        <sphere radius="0.1"/>
      </geometry>
    </collision>
    <inertial>
      <mass value="0.1"/>
      <inertia ixx="0.0004" ixy="0.0" ixz="0.0" iyy="0.0004" iyz="0.0" izz="0.0004"/>
    </inertial>
  </link>

  <joint name="front_caster_joint" type="fixed">
    <parent link="chassis"/>
    <child link="front_caster"/>
    <origin xyz="0.3 0 -0.3" rpy="0 0 0"/>
  </joint>

  <gazebo reference="front_caster">
    <mu1>0.0</mu1>
    <mu2>0.0</mu2>
  </gazebo>

  <!-- Rear Caster -->
  <link name="rear_caster">
    <visual>
      <geometry>
        <sphere radius="0.1"/>
      </geometry>
      <material name="blue"/>
    </visual>
    <collision>
      <geometry>
        <sphere radius="0.1"/>
      </geometry>
    </collision>
    <inertial>
      <mass value="0.1"/>
      <inertia ixx="0.0004" ixy="0.0" ixz="0.0" iyy="0.0004" iyz="0.0" izz="0.0004"/>
    </inertial>
  </link>

  <joint name="rear_caster_joint" type="fixed">
    <parent link="chassis"/>
    <child link="rear_caster"/>
    <origin xyz="-0.3 0 -0.3" rpy="0 0 0"/>
  </joint>

  <gazebo reference="rear_caster">
    <mu1>0.0</mu1>
    <mu2>0.0</mu2>
  </gazebo>

  <link name="lidar_dome">
    <visual>
      <geometry>
        <sphere radius="0.03125"/>
      </geometry>
      <material name="green"/>
    </visual>
    <collision>
      <geometry>
        <sphere radius="0.03125"/>
      </geometry>
    </collision>
    <inertial>
      <mass value="0.5"/>
      <inertia ixx="0.0002" ixy="0.0" ixz="0.0" iyy="0.0002" iyz="0.0" izz="0.0002"/>
    </inertial>
  </link>

  <joint name="lidar_joint" type="fixed">
    <parent link="chassis"/>
    <child link="lidar_dome"/>
    <origin xyz="0.3 0 0.0375" rpy="0 0 0"/>
  </joint>

  <gazebo reference="lidar_dome">
    <sensor name="lidar_sensor" type="gpu_lidar">
      <always_on>true</always_on>
      <visualize>true</visualize>
      <update_rate>10</update_rate>
      <topic>scan</topic>
      <gz:frame_id>lidar_dome</gz:frame_id>
      <lidar>
        <scan>
          <horizontal>
            <samples>360</samples>
            <resolution>1</resolution>
            <min_angle>-3.14159</min_angle>
            <max_angle>3.14159</max_angle>
          </horizontal>
        </scan>
        <range>
          <min>0.15</min>
          <max>10.0</max>
          <resolution>0.01</resolution>
        </range>
      </lidar>
    </sensor>
  </gazebo>
<gazebo>
    <plugin filename="gz-sim-diff-drive-system" name="gz::sim::systems::DiffDrive">
      <left_joint>left_wheel_joint</left_joint>
      <right_joint>right_wheel_joint</right_joint>
      <wheel_separation>0.875</wheel_separation>
      <wheel_radius>0.4</wheel_radius>
      <odom_publish_frequency>30</odom_publish_frequency>
      <topic>cmd_vel</topic>
      <odom_topic>odom</odom_topic>
      <frame_id>odom</frame_id>
      <child_frame_id>chassis</child_frame_id>
    </plugin>
  </gazebo>
  <gazebo>
    <plugin filename="gz-sim-joint-state-publisher-system" name="gz::sim::systems::JointStatePublisher">
      <topic>joint_states</topic>
      <joint_name>left_wheel_joint</joint_name>
      <joint_name>right_wheel_joint</joint_name>
    </plugin>
  </gazebo>  
</robot>