<?xml version="1.0"?>
<robot name="basic_robot">
  <material name="blue">
    <color rgba="0 0 1 1"/>
  </material>
  <material name="red">
    <color rgba="1 0 0 1"/>
  </material>
  <material name="green">
    <color rgba="0 1 0 1"/>
  </material>

  <link name="chassis">
    <visual>
      <geometry>
        <box size="0.825 0.825 0.075"/>
      </geometry>
    </visual>
  </link>

  <link name="left_wheel">
    <visual>
      <geometry>
        <cylinder radius="0.4" length="0.05"/>
      </geometry>
      <material name="blue"/>
    </visual>
    <visual>
      <origin xyz="0.2 0 0" rpy="0 0 0"/>
      <geometry>
        <box size="0.1 0.1 0.06"/>
      </geometry>
      <material name="green"/>
    </visual>
  </link>

  <joint name="left_wheel_joint" type="continuous">
    <parent link="chassis"/>
    <child link="left_wheel"/>
    <origin xyz="0 0.4375 0" rpy="-1.570796 0 0"/>
    <axis xyz="0 0 1"/>
  </joint>

  <link name="right_wheel">
    <visual>
      <geometry>
        <cylinder radius="0.4" length="0.05"/>
      </geometry>
      <material name="red"/>
    </visual>
    <visual>
      <origin xyz="0.2 0 0" rpy="0 0 0"/>
      <geometry>
        <box size="0.1 0.1 0.06"/>
      </geometry>
      <material name="green"/>
    </visual>
  </link>

  <joint name="right_wheel_joint" type="continuous">
    <parent link="chassis"/>
    <child link="right_wheel"/>
    <origin xyz="0 -0.4375 0" rpy="-1.570796 0 0"/>
    <axis xyz="0 0 1"/>
  </joint>

  <link name="lidar_dome">
    <visual>
      <geometry>
        <sphere radius="0.03125"/>
      </geometry>
      <material name="green"/>
    </visual>
  </link>

  <joint name="lidar_joint" type="fixed">
    <parent link="chassis"/>
    <child link="lidar_dome"/>
    <origin xyz="0.3 0 0.0375" rpy="0 0 0"/>
  </joint>
</robot>
